Workbook
Name IQ_CH: 110000
Name IQ_CQ: 5000
Name IQ_CY: 10000
Name IQ_DAILY: 500000
Name IQ_FH: 100000
Name IQ_FQ: 500
Name IQ_FY: 1000
Name IQ_LTM: 2000
Name IQ_MONTH: 15000
Name IQ_NTM: 6000
Name IQ_WEEK: 50000
Name IQ_YTD: 3000
Name UPDATE: 'Data Sheet'!$E$1
Name UPDATE: #REF!

Sheet Data Sheet
A1: COMPANY NAME | B1: TATA MOTORS PASSENGER VEHICLES LTD | E1: =IF(B2<>B3, "A NEW VERSION OF THE WORKSHEET IS AVAILABLE", "")
A2: LATEST VERSION | B2: 2.1 | E2: PLEASE DO NOT MAKE ANY CHANGES TO THIS SHEET
A3: CURRENT VERSION | B3: 2.1
A5: META
A6: Number of shares | B6: =IF(B9>0, B9/B8, 0) -> 368.28915
A7: Face Value | B7: 2
A8: Current Price | B8: 334.5
A9: Market Capitalization | B9: 123192.72
A15: PROFIT & LOSS
A16: Report Date | B16: 42825 | C16: 43190 | D16: 43555 | E16: 43921 | F16: 44286 | G16: 44651 | H16: 45016 | I16: 45382 | J16: 45747 | K16: 46112
A17: Sales | B17: 269692.51 | C17: 291550.48 | D17: 301938.4 | E17: 261067.97 | F17: 249794.75 | G17: 278453.62 | H17: 345966.97 | I17: 434016 | J17: 366094 | K17: 335582
A18: Raw Material Cost | B18: 173294.08 | C18: 187896.58 | D18: 194267.91 | E18: 164899.82 | F18: 153607.36 | G18: 179295.33 | H18: 231251.26 | I18: 274321 | J18: 219372 | K18: 212421
A19: Change in Inventory | B19: 7399.92 | C19: 2046.58 | D19: -2053.28 | E19: -2231.19 | F19: -4684.16 | G19: -1590.49 | H19: 4781.62 | I19: 1566 | J19: -2060 | K19: -1661
A20: Power and Fuel | B20: 1159.82 | C20: 1308.08 | D20: 1585.93 | E20: 1264.95 | F20: 1112.87 | G20: 2178.29 | H20: 2513.33 | I20: 2189 | J20: 1832 | K20: 1836
A21: Other Mfr. Exp | B21: 10067.37 | C21: 10971.66 | D21: 11694.54 | E21: 11541.51 | F21: 8273.17 | G21: 9427.38 | H21: 11765.97 | I21: 17446 | J21: 16684 | K21: 16905
A22: Employee Cost | B22: 28332.89 | C22: 30300.09 | D22: 33243.87 | E22: 30438.6 | F22: 27648.48 | G22: 30808.52 | H22: 33654.7 | I22: 41990 | J22: 42110 | K22: 45150
A23: Selling and admin | B23: 30039.38 | C23: 31004.58 | D23: 32719.8 | E23: 29248.32 | F23: 23015.79 | G23: 29205.4 | H23: 34839.19 | I23: 42765 | J23: 42908 | K23: 49582
A24: Other Expenses | B24: 4610.2 | C24: 658.39 | D24: 1708.74 | E24: 3456.51 | F24: -834.51 | G24: 1228.12 | H24: 4908.34 | I24: -938 | J24: -6865 | K24: -10692
A25: Other Income | B25: 1869.1 | C25: 5932.73 | D25: -26686.25 | E25: 101.71 | F25: -11117.83 | G25: 2424.05 | H25: 6663.97 | I25: 4807 | J25: 14219 | K25: 86291
A26: Depreciation | B26: 17904.99 | C26: 21553.59 | D26: 23590.63 | E26: 21425.43 | F26: 23546.71 | G26: 24835.69 | H26: 24860.36 | I26: 27239 | J26: 21102 | K26: 19784
A27: Interest | B27: 4238.01 | C27: 4681.79 | D27: 5758.6 | E27: 7243.33 | F27: 8097.17 | G27: 9311.86 | H27: 10225.48 | I27: 7594 | J27: 3901 | K27: 2827
... A30: Net profit | B30: 7454.36 | C30: 8988.91 | D30: -28826.23 | E30: -12070.85 | F30: -13451.39 | G30: -11441.47 | H30: 2414.29 | I30: 31399 | J30: 27830 | K30: 82390
A31: Dividend Amount | H31: 766.02 | I31: 2301 | J31: 2208 | K31: 1105.5
A40: Quarters
A41: Report Date | B41: 45382 | C41: 45473 | D41: 45565 | E41: 45657 | F41: 45747 | G41: 45838 | H41: 45930 | I41: 46022 | J41: 46112 | K41: 46203
A42: Sales | B42: 119033 | C42: 107102 | D42: 83656 | E42: 94472 | F42: 98377 | G42: 87677 | H42: 72349 | I42: 70108 | J42: 105447 | K42: 95799
A43: Expenses | B43: 102348 | C43: 91854 | D43: 73742 | E43: 84070 | F43: 83990 | G43: 79515 | H43: 73753 | I43: 69229 | J43: 94188 | K43: 89623
A44: Other Income | B44: 1412 | C44: 6553 | D44: 1920 | E44: 2730 | F44: 2361 | G44: 2690 | H44: 81507 | I44: 39 | J44: 1877 | K44: 1113
A45: Depreciation | B45: 7143 | C45: 6565 | D45: 5467 | E45: 4863 | F45: 4717 | G45: 4851 | H45: 4871 | I45: 4969 | J45: 5092 | K45: 4880
A46: Interest | B46: 1645 | C46: 1471 | D46: 1094 | E46: 843 | F46: 828 | G46: 692 | H46: 686 | I46: 682 | J46: 767 | K46: 835
A47: Profit before tax | B47: 9309 | C47: 13765 | D47: 5273 | E47: 7426 | F47: 11203 | G47: 5309 | H47: 74546 | I47: -4733 | J47: 7277 | K47: 1574
A48: Tax | B48: -8219 | C48: 3178 | D48: 1752 | E48: 1942 | F48: 2647 | G48: 1306 | H48: -1702 | I48: -1250 | J48: 1399 | K48: 715
A49: Net profit | B49: 17407 | C49: 10514 | D49: 3446 | E49: 5406 | F49: 8470 | G49: 3924 | H49: 76170 | I49: -3486 | J49: 5783 | K49: 775
A50: Operating Profit | B50: 16685 | C50: 15248 | D50: 9914 | E50: 10402 | F50: 14387 | G50: 8162 | H50: -1404 | I50: 879 | J50: 11259 | K50: 6176
A55: BALANCE SHEET
A56: Report Date | B56: 42825 | C56: 43190 | D56: 43555 | E56: 43921 | F56: 44286 | G56: 44651 | H56: 45016 | I56: 45382 | J56: 45747 | K56: 46112
A57: Equity Share Capital | B57: 679.22 | C57: 679.22 | D57: 679.22 | E57: 719.54 | F57: 765.81 | G57: 765.88 | H57: 766.02 | I57: 767 | J57: 736 | K57: 737
A58: Reserves | B58: 57382.67 | C58: 94748.69 | D58: 59500.34 | E58: 62358.99 | F58: 54480.91 | G58: 43795.36 | H58: 44555.77 | I58: 84151 | J58: 115408 | K58: 111331
A59: Borrowings | B59: 78603.98 | C59: 88950.47 | D59: 106175.34 | E59: 124787.64 | F59: 142130.57 | G59: 146449.03 | H59: 134113.44 | I59: 107264 | J59: 71540 | K59: 79109
A60: Other Liabilities | B60: 135914.49 | C60: 142813.43 | D60: 139348.59 | E60: 132313.22 | F60: 144192.62 | G60: 138051.22 | H60: 155239.2 | I60: 177339 | J60: 189289 | K60: 188012
...

Sheet Income Statement
B3: ="Financial Statements "&'Data Sheet'!B1 -> Financial Statements TATA MOTORS PASSENGER VEHICLES LTD
B4: Year | D4: ='Data Sheet'!B16 -> 42825 | E4: ='Data Sheet'!C16 -> 43190 | F4: ='Data Sheet'!D16 -> 43555 | G4: ='Data Sheet'!E16 -> 43921 | H4: ='Data Sheet'!F16 -> 44286 | I4: ='Data Sheet'!G16 -> 44651 | J4: ='Data Sheet'!H16 -> 45016 | K4: ='Data Sheet'!I16 -> 45382 | ... M4: ='Data Sheet'!K16 -> 46112
A6: # | B6: Income Statement | D6: {=_xlfn.SEQUENCE(,10,0,0)} -> 0 | E6: 0 | F6: 0 | G6: 0 | H6: 0 | I6: 0 | J6: 0 | K6: 0 | L6: 0 | M6: 0
B7: Sales | D7: {=IFERROR('Data Sheet'!B17,_xlfn.ANCHORARRAY(D6))} -> 269692.51 | E7: {=IFERROR('Data Sheet'!C17,_xlfn.ANCHORARRAY(E6))} -> 291550.48 | F7: {=IFERROR('Data Sheet'!D17,_xlfn.ANCHORARRAY(F6))} -> 301938.4 | G7: {=IFERROR('Data Sheet'!E17,_xlfn.ANCHORARRAY(G6))} -> 261067.97 | H7: {=IFERROR('Data Sheet'!F17,_xlfn.ANCHORARRAY(H6))} -> 249794.75 | I7: {=IFERROR('Data Sheet'!G17,_xlfn.ANCHORARRAY(I6))} -> 278453.62 | J7: {=IFERROR('Data Sheet'!H17,_xlfn.ANCHORARRAY(J6))} -> 345966.97 | K7: {=IFERROR('Data Sheet'!I17,_xlfn.ANCHORARRAY(K6))} -> 434016 | ... M7: {=IFERROR('Data Sheet'!K17,_xlfn.ANCHORARRAY(M6))} -> 335582
B8: Sales Growth | E8: =E7/D7-1 -> 0.081047746 | F8: =F7/E7-1 -> 0.035629919 | G8: =G7/F7-1 -> -0.13536016 | H8: =H7/G7-1 -> -0.043181168 | I8: =I7/H7-1 -> 0.11472967 | J8: =J7/I7-1 -> 0.24245815 | K8: =K7/J7-1 -> 0.25450126 | L8: =L7/K7-1 -> -0.15649653 | M8: =M7/L7-1 -> -0.083344715
B9: COGS | D9: {=IFERROR(SUM('Data Sheet'!B18,'Data Sheet'!B20:B22)-1*'Data Sheet'!B19,_xlfn.ANCHORARRAY(D6))} -> 205454.24 | E9: {=IFERROR(SUM('Data Sheet'!C18,'Data Sheet'!C20:C22)-1*'Data Sheet'!C19,_xlfn.ANCHORARRAY(E6))} -> 228429.83 | F9: {=IFERROR(SUM('Data Sheet'!D18,'Data Sheet'!D20:D22)-1*'Data Sheet'!D19,_xlfn.ANCHORARRAY(F6))} -> 242845.53 | G9: {=IFERROR(SUM('Data Sheet'!E18,'Data Sheet'!E20:E22)-1*'Data Sheet'!E19,_xlfn.ANCHORARRAY(G6))} -> 210376.07 | H9: {=IFERROR(SUM('Data Sheet'!F18,'Data Sheet'!F20:F22)-1*'Data Sheet'!F19,_xlfn.ANCHORARRAY(H6))} -> 195326.04 | I9: {=IFERROR(SUM('Data Sheet'!G18,'Data Sheet'!G20:G22)-1*'Data Sheet'!G19,_xlfn.ANCHORARRAY(I6))} -> 223300.01 | J9: {=IFERROR(SUM('Data Sheet'!H18,'Data Sheet'!H20:H22)-1*'Data Sheet'!H19,_xlfn.ANCHORARRAY(J6))} -> 274403.64 | K9: {=IFERROR(SUM('Data Sheet'!I18,'Data Sheet'!I20:I22)-1*'Data Sheet'!I19,_xlfn.ANCHORARRAY(K6))} -> 334380 | ... M9: {=IFERROR(SUM('Data Sheet'!K18,'Data Sheet'!K20:K22)-1*'Data Sheet'!K19,_xlfn.ANCHORARRAY(M6))} -> 277973
B10: COGS % Sales | D10: =D9/D7 -> 0.76180922 | E10: =E9/E7 -> 0.7835001 | F10: =F9/F7 -> 0.80428833 | G10: =G9/G7 -> 0.80582873 | H10: =H9/H7 -> 0.78194614 | I10: =I9/I7 -> 0.80192892 | J10: =J9/J7 -> 0.79314982 | K10: =K9/K7 -> 0.77043243 | ... M10: =M9/M7 -> 0.82833108
B12: Gross Profit | D12: =D7-D9 -> 64238.27 | E12: =E7-E9 -> 63120.65 | F12: =F7-F9 -> 59092.87 | G12: =G7-G9 -> 50691.9 | H12: =H7-H9 -> 54468.71 | I12: =I7-I9 -> 55153.61 | J12: =J7-J9 -> 71563.33 | K12: =K7-K9 -> 99636 | ... M12: =M7-M9 -> 57609
B14: ='Data Sheet'!A23 -> Selling and admin | D14: {=IFERROR('Data Sheet'!B23,_xlfn.ANCHORARRAY('Income Statement'!D6))} -> 30039.38 | E14: {=IFERROR('Data Sheet'!C23,_xlfn.ANCHORARRAY('Income Statement'!E6))} -> 31004.58 | F14: {=IFERROR('Data Sheet'!D23,_xlfn.ANCHORARRAY('Income Statement'!F6))} -> 32719.8 | G14: {=IFERROR('Data Sheet'!E23,_xlfn.ANCHORARRAY('Income Statement'!G6))} -> 29248.32 | H14: {=IFERROR('Data Sheet'!F23,_xlfn.ANCHORARRAY('Income Statement'!H6))} -> 23015.79 | I14: {=IFERROR('Data Sheet'!G23,_xlfn.ANCHORARRAY('Income Statement'!I6))} -> 29205.4 | J14: {=IFERROR('Data Sheet'!H23,_xlfn.ANCHORARRAY('Income Statement'!J6))} -> 34839.19 | K14: {=IFERROR('Data Sheet'!I23,_xlfn.ANCHORARRAY('Income Statement'!K6))} -> 42765 | ... M14: {=IFERROR('Data Sheet'!K23,_xlfn.ANCHORARRAY('Income Statement'!M6))} -> 49582
B15: S&A % on sales | D15: =D14/D7 -> 0.11138381 | E15: =E14/E7 -> 0.10634378 | F15: =F14/F7 -> 0.10836581 | G15: =G14/G7 -> 0.11203335 | H15: =H14/H7 -> 0.092138806 | I15: =I14/I7 -> 0.10488425 | J15: =J14/J7 -> 0.10070091 | K15: =K14/K7 -> 0.098533234 | ... M15: =M14/M7 -> 0.14774928
B17: Other Expenses | D17: {=IFERROR('Data Sheet'!B24,_xlfn.ANCHORARRAY(D6))} -> 4610.2 | E17: {=IFERROR('Data Sheet'!C24,_xlfn.ANCHORARRAY(E6))} -> 658.39 | F17: {=IFERROR('Data Sheet'!D24,_xlfn.ANCHORARRAY(F6))} -> 1708.74 | G17: {=IFERROR('Data Sheet'!E24,_xlfn.ANCHORARRAY(G6))} -> 3456.51 | H17: {=IFERROR('Data Sheet'!F24,_xlfn.ANCHORARRAY(H6))} -> -834.51 | I17: {=IFERROR('Data Sheet'!G24,_xlfn.ANCHORARRAY(I6))} -> 1228.12 | J17: {=IFERROR('Data Sheet'!H24,_xlfn.ANCHORARRAY(J6))} -> 4908.34 | K17: {=IFERROR('Data Sheet'!I24,_xlfn.ANCHORARRAY(K6))} -> -938 | ... M17: {=IFERROR('Data Sheet'!K24,_xlfn.ANCHORARRAY(M6))} -> -10692
B19: EBITDA | D19: =D12-D14-ABS(D17) -> 29588.69 | E19: =E12-E14-ABS(E17) -> 31457.68 | F19: =F12-F14-ABS(F17) -> 24664.33 | G19: =G12-G14-ABS(G17) -> 17987.07 | H19: =H12-H14-ABS(H17) -> 30618.41 | I19: =I12-I14-ABS(I17) -> 24720.09 | J19: =J12-J14-ABS(J17) -> 31815.8 | K19: =K12-K14-ABS(K17) -> 55933 | ... M19: =M12-M14-ABS(M17) -> -2665
B20: EBITDA % on sales | D20: =D19/D7 -> 0.10971269 | E20: =E19/E7 -> 0.10789788 | F20: =F19/F7 -> 0.081686629 | G20: =G19/G7 -> 0.068898034 | H20: =H19/H7 -> 0.12257427 | I20: =I19/I7 -> 0.088776328 | J20: =J19/J7 -> 0.091961958 | K20: =K19/K7 -> 0.12887313 | ... M20: =M19/M7 -> -0.0079414271
B22: Other Income | D22: {=IFERROR('Data Sheet'!B25,_xlfn.ANCHORARRAY(D6))} -> 1869.1 | E22: {=IFERROR('Data Sheet'!C25,_xlfn.ANCHORARRAY(E6))} -> 5932.73 | F22: {=IFERROR('Data Sheet'!D25,_xlfn.ANCHORARRAY(F6))} -> -26686.25 | G22: {=IFERROR('Data Sheet'!E25,_xlfn.ANCHORARRAY(G6))} -> 101.71 | H22: {=IFERROR('Data Sheet'!F25,_xlfn.ANCHORARRAY(H6))} -> -11117.83 | I22: {=IFERROR('Data Sheet'!G25,_xlfn.ANCHORARRAY(I6))} -> 2424.05 | J22: {=IFERROR('Data Sheet'!H25,_xlfn.ANCHORARRAY(J6))} -> 6663.97 | K22: {=IFERROR('Data Sheet'!I25,_xlfn.ANCHORARRAY(K6))} -> 4807 | ... M22: {=IFERROR('Data Sheet'!K25,_xlfn.ANCHORARRAY(M6))} -> 86291
B24: Depreciation | D24: {=IFERROR('Data Sheet'!B26,_xlfn.ANCHORARRAY(D6))} -> 17904.99 | E24: {=IFERROR('Data Sheet'!C26,_xlfn.ANCHORARRAY(E6))} -> 21553.59 | F24: {=IFERROR('Data Sheet'!D26,_xlfn.ANCHORARRAY(F6))} -> 23590.63 | G24: {=IFERROR('Data Sheet'!E26,_xlfn.ANCHORARRAY(G6))} -> 21425.43 | H24: {=IFERROR('Data Sheet'!F26,_xlfn.ANCHORARRAY(H6))} -> 23546.71 | I24: {=IFERROR('Data Sheet'!G26,_xlfn.ANCHORARRAY(I6))} -> 24835.69 | J24: {=IFERROR('Data Sheet'!H26,_xlfn.ANCHORARRAY(J6))} -> 24860.36 | K24: {=IFERROR('Data Sheet'!I26,_xlfn.ANCHORARRAY(K6))} -> 27239 | ... M24: {=IFERROR('Data Sheet'!K26,_xlfn.ANCHORARRAY(M6))} -> 19784
B25: Dep % on sales | D25: =D24/D7 -> 0.066390387 | E25: =E24/E7 -> 0.073927472 | F25: =F24/F7 -> 0.078130605 | G25: =G24/G7 -> 0.082068398 | H25: =H24/H7 -> 0.094264231 | I25: =I24/I7 -> 0.089191478 | J25: =J24/J7 -> 0.071857611 | K25: =K24/K7 -> 0.062760359 | ... M25: =M24/M7 -> 0.058954294
B27: EBIT (Operating Income) | D27: =D19+D22-D24 -> 13552.8 | E27: =E19+E22-E24 -> 15836.82 | F27: =F19+F22-F24 -> -25612.55 | G27: =G19+G22-G24 -> -3336.65 | H27: =H19+H22-H24 -> -4046.13 | I27: =I19+I22-I24 -> 2308.45 | J27: =J19+J22-J24 -> 13619.41 | K27: =K19+K22-K24 -> 33501 | ... M27: =M19+M22-M24 -> 63842
B29: Interest | D29: {=IFERROR('Data Sheet'!B27,_xlfn.ANCHORARRAY(D6))} -> 4238.01 | E29: {=IFERROR('Data Sheet'!C27,_xlfn.ANCHORARRAY(E6))} -> 4681.79 | F29: {=IFERROR('Data Sheet'!D27,_xlfn.ANCHORARRAY(F6))} -> 5758.6 | G29: {=IFERROR('Data Sheet'!E27,_xlfn.ANCHORARRAY(G6))} -> 7243.33 | H29: {=IFERROR('Data Sheet'!F27,_xlfn.ANCHORARRAY(H6))} -> 8097.17 | I29: {=IFERROR('Data Sheet'!G27,_xlfn.ANCHORARRAY(I6))} -> 9311.86 | J29: {=IFERROR('Data Sheet'!H27,_xlfn.ANCHORARRAY(J6))} -> 10225.48 | K29: {=IFERROR('Data Sheet'!I27,_xlfn.ANCHORARRAY(K6))} -> 7594 | ... M29: {=IFERROR('Data Sheet'!K27,_xlfn.ANCHORARRAY(M6))} -> 2827
B30: Interest % on sales | D30: =D29/D7 -> 0.01571423 | E30: =E29/E7 -> 0.016058248 | F30: =F29/F7 -> 0.019072102 | G30: =G29/G7 -> 0.027744997 | H30: =H29/H7 -> 0.032415293 | I30: =I29/I7 -> 0.033441332 | J30: =J29/J7 -> 0.029556232 | K30: =K29/K7 -> 0.017497051 | ... M30: =M29/M7 -> 0.0084241705
B32: EBT | D32: =D27-D29 -> 9314.79 | E32: =E27-E29 -> 11155.03 | F32: =F27-F29 -> -31371.15 | G32: =G27-G29 -> -10579.98 | H32: =H27-H29 -> -12143.3 | I32: =I27-I29 -> -7003.41 | J32: =J27-J29 -> 3393.93 | K32: =K27-K29 -> 25907 | ... M32: =M27-M29 -> 61015
B33: EBT % on Sales | D33: =D32/D7 -> 0.034538557 | E33: =E32/E7 -> 0.038261059 | F33: =F32/F7 -> -0.10389917 | G33: =G32/G7 -> -0.040525768 | H33: =H32/H7 -> -0.048613111 | I33: =I32/I7 -> -0.025151083 | J33: =J32/J7 -> 0.0098099827 | K33: =K32/K7 -> 0.059691348 | ... M33: =M32/M7 -> 0.18181845
B35: TAX | D35: {=IFERROR('Data Sheet'!B29,_xlfn.ANCHORARRAY(D6))} -> 3251.23 | E35: {=IFERROR('Data Sheet'!C29,_xlfn.ANCHORARRAY(E6))} -> 4341.93 | F35: {=IFERROR('Data Sheet'!D29,_xlfn.ANCHORARRAY(F6))} -> -2437.45 | G35: {=IFERROR('Data Sheet'!E29,_xlfn.ANCHORARRAY(G6))} -> 395.25 | H35: {=IFERROR('Data Sheet'!F29,_xlfn.ANCHORARRAY(H6))} -> 2541.86 | I35: {=IFERROR('Data Sheet'!G29,_xlfn.ANCHORARRAY(I6))} -> 4231.29 | J35: {=IFERROR('Data Sheet'!H29,_xlfn.ANCHORARRAY(J6))} -> 704.06 | K35: {=IFERROR('Data Sheet'!I29,_xlfn.ANCHORARRAY(K6))} -> -4024 | ... M35: {=IFERROR('Data Sheet'!K29,_xlfn.ANCHORARRAY(M6))} -> -246
B36: Effective Tax Growth | D36: =D35/D32 -> 0.34903954 | E36: =E35/E32 -> 0.38923517 | F36: =F35/F32 -> 0.077697184 | G36: =G35/G32 -> -0.037358294 | H36: =H35/H32 -> -0.20932201 | I36: =I35/I32 -> -0.60417568 | J36: =J35/J32 -> 0.20744682 | K36: =K35/K32 -> -0.15532482 | ... M36: =M35/M32 -> -0.0040317955
B38: PAT | D38: =D32-D35 -> 6063.56 | E38: =E32-E35 -> 6813.1 | F38: =F32-F35 -> -28933.7 | G38: =G32-G35 -> -10975.23 | H38: =H32-H35 -> -14685.16 | I38: =I32-I35 -> -11234.7 | J38: =J32-J35 -> 2689.87 | K38: =K32-K35 -> 29931 | ... M38: =M32-M35 -> 61261
B39: PAT % on sales | D39: =D38/D7 -> 0.022483235 | E39: =E38/E7 -> 0.023368509 | F39: =F38/F7 -> -0.0958265 | G39: =G38/G7 -> -0.042039742 | H39: =H38/H7 -> -0.058788906 | I39: =I38/I7 -> -0.040346755 | J39: =J38/J7 -> 0.007774933 | K39: =K38/K7 -> 0.068962895 | ... M39: =M38/M7 -> 0.18255151
B41: No.of Equity Shares | D41: ='Data Sheet'!B93 -> 288.73 | E41: ='Data Sheet'!C93 -> 288.73 | F41: ='Data Sheet'!D93 -> 288.73 | G41: ='Data Sheet'!E93 -> 308.9 | H41: ='Data Sheet'!F93 -> 332.03 | I41: ='Data Sheet'!G93 -> 332.07 | J41: ='Data Sheet'!H93 -> 332.13 | K41: ='Data Sheet'!I93 -> 332.37 | ... M41: ='Data Sheet'!K93 -> 368.24
B43: EPS | D43: =IFERROR(D38/D41,0) -> 21.000797 | E43: =IFERROR(E38/E41,0) -> 23.596786 | F43: =IFERROR(F38/F41,0) -> -100.21023 | G43: =IFERROR(G38/G41,0) -> -35.530042 | H43: =IFERROR(H38/H41,0) -> -44.228413 | I43: =IFERROR(I38/I41,0) -> -33.832325 | J43: =IFERROR(J38/J41,0) -> 8.0988468 | K43: =IFERROR(K38/K41,0) -> 90.053254 | ... M43: =IFERROR(M38/M41,0) -> 166.36161
B45: Dividend Per Share | J45: ='Data Sheet'!H31/J41 -> 2.3063861 | K45: ='Data Sheet'!I31/K41 -> 6.9230075 | L45: ='Data Sheet'!J31/L41 -> 5.9978812 | M45: ='Data Sheet'!K31/M41 -> 3.0021182
B46: Dividend Payout Ratio | J46: =J45/J43 -> 0.28477956 | K46: =K45/K43 -> 0.076876817 | L46: =L45/L43 -> 0.15313129 | M46: =M45/M43 -> 0.018045739
B48: Retained Earnings | J48: =IFERROR(IF(J43>J45,1-J46,0),0) -> 0.71522044 | K48: =IFERROR(IF(K43>K45,1-K46,0),0) -> 0.92312318 | L48: =IFERROR(IF(L43>L45,1-L46,0),0) -> 0.84686871 | M48: =IFERROR(IF(M43>M45,1-M46,0),0) -> 0.98195426
J49: 1 | K49: 1 | L49: 1 | M49: 1

Sheet Balance Sheet
B3: ="Financial Statements "&'Data Sheet'!B1 -> Financial Statements TATA MOTORS PASSENGER VEHICLES LTD
B4: Year | D4: ='Data Sheet'!B16 -> 42825 | E4: ='Data Sheet'!C16 -> 43190 | F4: ='Data Sheet'!D16 -> 43555 | G4: ='Data Sheet'!E16 -> 43921 | H4: ='Data Sheet'!F16 -> 44286 | I4: ='Data Sheet'!G16 -> 44651 | J4: ='Data Sheet'!H16 -> 45016 | K4: ='Data Sheet'!I16 -> 45382 | ... M4: ='Data Sheet'!K16 -> 46112
B6: Balance Sheet | D6: {=_xlfn.SEQUENCE(,10,0,0)} -> 0 | E6: 0 | F6: 0 | G6: 0 | H6: 0 | I6: 0 | J6: 0 | K6: 0 | L6: 0 | M6: 0
B8: Equity Share Capital | D8: =IFERROR('Data Sheet'!B57,0) -> 679.22 | E8: =IFERROR('Data Sheet'!C57,0) -> 679.22 | F8: =IFERROR('Data Sheet'!D57,0) -> 679.22 | G8: =IFERROR('Data Sheet'!E57,0) -> 719.54 | H8: =IFERROR('Data Sheet'!F57,0) -> 765.81 | I8: =IFERROR('Data Sheet'!G57,0) -> 765.88 | J8: =IFERROR('Data Sheet'!H57,0) -> 766.02 | K8: =IFERROR('Data Sheet'!I57,0) -> 767 | ... M8: =IFERROR('Data Sheet'!K57,0) -> 737
B9: Reserves | D9: =IFERROR('Data Sheet'!B58,0) -> 57382.67 | E9: =IFERROR('Data Sheet'!C58,0) -> 94748.69 | F9: =IFERROR('Data Sheet'!D58,0) -> 59500.34 | G9: =IFERROR('Data Sheet'!E58,0) -> 62358.99 | H9: =IFERROR('Data Sheet'!F58,0) -> 54480.91 | I9: =IFERROR('Data Sheet'!G58,0) -> 43795.36 | J9: =IFERROR('Data Sheet'!H58,0) -> 44555.77 | K9: =IFERROR('Data Sheet'!I58,0) -> 84151 | ... M9: =IFERROR('Data Sheet'!K58,0) -> 111331
B10: Borrowings | D10: =IFERROR('Data Sheet'!B59,0) -> 78603.98 | E10: =IFERROR('Data Sheet'!C59,0) -> 88950.47 | F10: =IFERROR('Data Sheet'!D59,0) -> 106175.34 | G10: =IFERROR('Data Sheet'!E59,0) -> 124787.64 | H10: =IFERROR('Data Sheet'!F59,0) -> 142130.57 | I10: =IFERROR('Data Sheet'!G59,0) -> 146449.03 | J10: =IFERROR('Data Sheet'!H59,0) -> 134113.44 | K10: =IFERROR('Data Sheet'!I59,0) -> 107264 | ... M10: =IFERROR('Data Sheet'!K59,0) -> 79109
B11: Other Liabilities | D11: =IFERROR('Data Sheet'!B60,0) -> 135914.49 | E11: =IFERROR('Data Sheet'!C60,0) -> 142813.43 | F11: =IFERROR('Data Sheet'!D60,0) -> 139348.59 | G11: =IFERROR('Data Sheet'!E60,0) -> 132313.22 | H11: =IFERROR('Data Sheet'!F60,0) -> 144192.62 | I11: =IFERROR('Data Sheet'!G60,0) -> 138051.22 | J11: =IFERROR('Data Sheet'!H60,0) -> 155239.2 | K11: =IFERROR('Data Sheet'!I60,0) -> 177339 | ... M11: =IFERROR('Data Sheet'!K60,0) -> 188012
B12: Total Liablities | D12: =SUM(D8:D11) -> 272580.36 | E12: =SUM(E8:E11) -> 327191.81 | F12: =SUM(F8:F11) -> 305703.49 | G12: =SUM(G8:G11) -> 320179.39 | H12: =SUM(H8:H11) -> 341569.91 | I12: =SUM(I8:I11) -> 329061.49 | J12: =SUM(J8:J11) -> 334674.43 | K12: =SUM(K8:K11) -> 369521 | ... M12: =SUM(M8:M11) -> 379189
B14: Fixed Assets of net block | D14: =IFERROR('Data Sheet'!B62,0) -> 95944.08 | E14: =IFERROR('Data Sheet'!C62,0) -> 121413.86 | F14: =IFERROR('Data Sheet'!D62,0) -> 111234.47 | G14: =IFERROR('Data Sheet'!E62,0) -> 127107.14 | H14: =IFERROR('Data Sheet'!F62,0) -> 138707.61 | I14: =IFERROR('Data Sheet'!G62,0) -> 138855.45 | J14: =IFERROR('Data Sheet'!H62,0) -> 132079.76 | K14: =IFERROR('Data Sheet'!I62,0) -> 121285 | ... M14: =IFERROR('Data Sheet'!K62,0) -> 104656
B15: Capital Work in Progress | D15: =IFERROR('Data Sheet'!B63,0) -> 33698.84 | E15: =IFERROR('Data Sheet'!C63,0) -> 40033.5 | F15: =IFERROR('Data Sheet'!D63,0) -> 31883.84 | G15: =IFERROR('Data Sheet'!E63,0) -> 35622.29 | H15: =IFERROR('Data Sheet'!F63,0) -> 20963.93 | I15: =IFERROR('Data Sheet'!G63,0) -> 10251.09 | J15: =IFERROR('Data Sheet'!H63,0) -> 14274.5 | K15: =IFERROR('Data Sheet'!I63,0) -> 35698 | ... M15: =IFERROR('Data Sheet'!K63,0) -> 102654
B16: Investments | D16: =IFERROR('Data Sheet'!B64,0) -> 20337.92 | E16: =IFERROR('Data Sheet'!C64,0) -> 20812.75 | F16: =IFERROR('Data Sheet'!D64,0) -> 15770.72 | G16: =IFERROR('Data Sheet'!E64,0) -> 16308.48 | H16: =IFERROR('Data Sheet'!F64,0) -> 24620.28 | I16: =IFERROR('Data Sheet'!G64,0) -> 29379.53 | J16: =IFERROR('Data Sheet'!H64,0) -> 26379.16 | K16: =IFERROR('Data Sheet'!I64,0) -> 22971 | ... M16: =IFERROR('Data Sheet'!K64,0) -> 26313
B17: Other Assets | D17: =IFERROR('Data Sheet'!B65-SUM('Data Sheet'!B67:B69),0) -> 37360.78 | E17: =IFERROR('Data Sheet'!C65-SUM('Data Sheet'!C67:C69),0) -> 48286.86 | F17: =IFERROR('Data Sheet'!D65-SUM('Data Sheet'!D67:D69),0) -> 56155.74 | G17: =IFERROR('Data Sheet'!E65-SUM('Data Sheet'!E67:E69),0) -> 58784.94 | H17: =IFERROR('Data Sheet'!F65-SUM('Data Sheet'!F67:F69),0) -> 61717.96 | I17: =IFERROR('Data Sheet'!G65-SUM('Data Sheet'!G67:G69),0) -> 62223.77 | J17: =IFERROR('Data Sheet'!H65-SUM('Data Sheet'!H67:H69),0) -> 68432.09 | K17: =IFERROR('Data Sheet'!I65-SUM('Data Sheet'!I67:I69),0) -> 79020 | ... M17: =IFERROR('Data Sheet'!K65-SUM('Data Sheet'!K67:K69),0) -> 53137
B18: Total Non Current Assets | D18: =SUM(D14:D17) -> 187341.62 | E18: =SUM(E14:E17) -> 230546.97 | F18: =SUM(F14:F17) -> 215044.77 | G18: =SUM(G14:G17) -> 237822.85 | H18: =SUM(H14:H17) -> 246009.78 | I18: =SUM(I14:I17) -> 240709.84 | J18: =SUM(J14:J17) -> 241165.51 | K18: =SUM(K14:K17) -> 258974 | ... M18: =SUM(M14:M17) -> 286760
B20: Receivables | D20: =IFERROR('Data Sheet'!B67,0) -> 14075.55 | E20: =IFERROR('Data Sheet'!C67,0) -> 19893.3 | F20: =IFERROR('Data Sheet'!D67,0) -> 18996.17 | G20: =IFERROR('Data Sheet'!E67,0) -> 11172.69 | H20: =IFERROR('Data Sheet'!F67,0) -> 12679.08 | I20: =IFERROR('Data Sheet'!G67,0) -> 12442.12 | J20: =IFERROR('Data Sheet'!H67,0) -> 15737.97 | K20: =IFERROR('Data Sheet'!I67,0) -> 16952 | ... M20: =IFERROR('Data Sheet'!K67,0) -> 12619
B21: Inventory | D21: =IFERROR('Data Sheet'!B68,0) -> 35085.31 | E21: =IFERROR('Data Sheet'!C68,0) -> 42137.63 | F21: =IFERROR('Data Sheet'!D68,0) -> 39013.73 | G21: =IFERROR('Data Sheet'!E68,0) -> 37456.88 | H21: =IFERROR('Data Sheet'!F68,0) -> 36088.59 | I21: =IFERROR('Data Sheet'!G68,0) -> 35240.34 | J21: =IFERROR('Data Sheet'!H68,0) -> 40755.39 | K21: =IFERROR('Data Sheet'!I68,0) -> 47788 | ... M21: =IFERROR('Data Sheet'!K68,0) -> 50126
B22: Cash & Bank | D22: =IFERROR('Data Sheet'!B69,0) -> 36077.88 | E22: =IFERROR('Data Sheet'!C69,0) -> 34613.91 | F22: =IFERROR('Data Sheet'!D69,0) -> 32648.82 | G22: =IFERROR('Data Sheet'!E69,0) -> 33726.97 | H22: =IFERROR('Data Sheet'!F69,0) -> 46792.46 | I22: =IFERROR('Data Sheet'!G69,0) -> 40669.19 | J22: =IFERROR('Data Sheet'!H69,0) -> 37015.56 | K22: =IFERROR('Data Sheet'!I69,0) -> 45807 | ... M22: =IFERROR('Data Sheet'!K69,0) -> 29684
B23: Total Current Assets | D23: =SUM(D20:D22) -> 85238.74 | E23: =SUM(E20:E22) -> 96644.84 | F23: =SUM(F20:F22) -> 90658.72 | G23: =SUM(G20:G22) -> 82356.54 | H23: =SUM(H20:H22) -> 95560.13 | I23: =SUM(I20:I22) -> 88351.65 | J23: =SUM(J20:J22) -> 93508.92 | K23: =SUM(K20:K22) -> 110547 | ... M23: =SUM(M20:M22) -> 92429
B25: Total Assets | D25: =D23+D18 -> 272580.36 | E25: =E23+E18 -> 327191.81 | F25: =F23+F18 -> 305703.49 | G25: =G23+G18 -> 320179.39 | H25: =H23+H18 -> 341569.91 | I25: =I23+I18 -> 329061.49 | J25: =J23+J18 -> 334674.43 | K25: =K23+K18 -> 369521 | ... M25: =M23+M18 -> 379189
B27: CHECK | D27: =IF(D25=D12, "OK", "Error") -> OK | E27: =IF(E25=E12, "OK", "Error") -> OK | F27: =IF(F25=F12, "OK", "Error") -> OK | G27: =IF(G25=G12, "OK", "Error") -> OK | H27: =IF(H25=H12, "OK", "Error") -> OK | I27: =IF(I25=I12, "OK", "Error") -> OK | J27: =IF(J25=J12, "OK", "Error") -> OK | K27: =IF(K25=K12, "OK", "Error") -> OK | ... M27: =IF(M25=M12, "OK", "Error") -> OK

Sheet Cash Flow Statement
B2: ="Financial Statements "&'Data Sheet'!B1 -> Financial Statements TATA MOTORS PASSENGER VEHICLES LTD
B3: Year | D3: ='Data Sheet'!B16 -> 42825 | E3: ='Data Sheet'!C16 -> 43190 | F3: ='Data Sheet'!D16 -> 43555 | G3: ='Data Sheet'!E16 -> 43921 | H3: ='Data Sheet'!F16 -> 44286 | I3: ='Data Sheet'!G16 -> 44651 | J3: ='Data Sheet'!H16 -> 45016 | K3: ='Data Sheet'!I16 -> 45382 | ... M3: ='Data Sheet'!K16 -> 46112
B5: Cash Flow Statement | D5: {=_xlfn.SEQUENCE(,10,0,0)} -> 0 | E5: 0 | F5: 0 | G5: 0 | H5: 0 | I5: 0 | J5: 0 | K5: 0 | L5: 0 | M5: 0
B7: Profit from operations | D7: =IFERROR(Sheet1!E4,0) -> 28840 | E7: =IFERROR(Sheet1!F4,0) -> 33312 | F7: =IFERROR(Sheet1!G4,0) -> 28771 | G7: =IFERROR(Sheet1!H4,0) -> 23352 | H7: =IFERROR(Sheet1!I4,0) -> 31198 | I7: =IFERROR(Sheet1!J4,0) -> 26943 | J7: =IFERROR(Sheet1!K4,0) -> 41694 | K7: =IFERROR(Sheet1!L4,0) -> 65106 | ... M7: =IFERROR(Sheet1!N4,0) -> 25393
B8: Receivables | D8: =IFERROR(Sheet1!E5,0) -> -4152 | E8: =IFERROR(Sheet1!F5,0) -> -10688 | F8: =IFERROR(Sheet1!G5,0) -> -9109 | G8: =IFERROR(Sheet1!H5,0) -> 9950 | H8: =IFERROR(Sheet1!I5,0) -> -5505 | I8: =IFERROR(Sheet1!J5,0) -> 185 | J8: =IFERROR(Sheet1!K5,0) -> -2213 | K8: =IFERROR(Sheet1!L5,0) -> -1876 | ... M8: =IFERROR(Sheet1!N5,0) -> -1587
B9: Inventory | D9: =IFERROR(Sheet1!E6,0) -> -6621 | E9: =IFERROR(Sheet1!F6,0) -> -3560 | F9: =IFERROR(Sheet1!G6,0) -> 2069 | G9: =IFERROR(Sheet1!H6,0) -> 2326 | H9: =IFERROR(Sheet1!I6,0) -> 3814 | I9: =IFERROR(Sheet1!J6,0) -> 472 | J9: =IFERROR(Sheet1!K6,0) -> -5665 | K9: =IFERROR(Sheet1!L6,0) -> -7265 | ... M9: =IFERROR(Sheet1!N6,0) -> -4318
B10: Payables | D10: =IFERROR(Sheet1!E7,0) -> 9301 | E10: =IFERROR(Sheet1!F7,0) -> 7320 | F10: =IFERROR(Sheet1!G7,0) -> -4692 | G10: =IFERROR(Sheet1!H7,0) -> -8085 | H10: =IFERROR(Sheet1!I7,0) -> 5748 | I10: =IFERROR(Sheet1!J7,0) -> -7012 | J10: =IFERROR(Sheet1!K7,0) -> 6945 | K10: =IFERROR(Sheet1!L7,0) -> 13706 | ... M10: =IFERROR(Sheet1!N7,0) -> -1973
B11: Loans Advances | D11: =IFERROR(Sheet1!E8,0) -> 0 | E11: =IFERROR(Sheet1!F8,0) -> 0 | F11: =IFERROR(Sheet1!G8,0) -> 0 | G11: =IFERROR(Sheet1!H8,0) -> 0 | H11: =IFERROR(Sheet1!I8,0) -> 0 | I11: =IFERROR(Sheet1!J8,0) -> 0 | J11: =IFERROR(Sheet1!K8,0) -> 0 | K11: =IFERROR(Sheet1!L8,0) -> 0 | ... M11: =IFERROR(Sheet1!N8,0) -> 0
B12: Operating borrowings | D12: =IFERROR(Sheet1!E9,0) -> 4727 | E12: =IFERROR(Sheet1!F9,0) -> 494 | F12: =IFERROR(Sheet1!G9,0) -> 4512 | G12: =IFERROR(Sheet1!H9,0) -> 875 | H12: =IFERROR(Sheet1!I9,0) -> -4150 | I12: =IFERROR(Sheet1!J9,0) -> -4396 | J12: =IFERROR(Sheet1!K9,0) -> -2194 | K12: =IFERROR(Sheet1!L9,0) -> 2760 | ... M12: =IFERROR(Sheet1!N9,0) -> -1160
B13: Other WC items | D13: =IFERROR(Sheet1!E10,0) -> 3254 | E13: =IFERROR(Sheet1!F10,0) -> -6434 | F13: =IFERROR(Sheet1!G10,0) -> -7221 | G13: =IFERROR(Sheet1!H10,0) -> 5065 | H13: =IFERROR(Sheet1!I10,0) -> -93 | I13: =IFERROR(Sheet1!J10,0) -> -10750 | J13: =IFERROR(Sheet1!K10,0) -> -3127 | K13: =IFERROR(Sheet1!L10,0) -> 7325 | ... M13: =IFERROR(Sheet1!N10,0) -> -9038
B14: Direct taxes | D14: =IFERROR(Sheet1!E11,0) -> -1895 | E14: =IFERROR(Sheet1!F11,0) -> -3021 | F14: =IFERROR(Sheet1!G11,0) -> -2659 | G14: =IFERROR(Sheet1!H11,0) -> -1785 | H14: =IFERROR(Sheet1!I11,0) -> -2105 | I14: =IFERROR(Sheet1!J11,0) -> -1910 | J14: =IFERROR(Sheet1!K11,0) -> -3179 | K14: =IFERROR(Sheet1!L11,0) -> -4516 | ... M14: =IFERROR(Sheet1!N11,0) -> -3314
B15: Cash from Operating Activities | D15: =SUM(D7:D14) -> 33454 | E15: =SUM(E7:E14) -> 17423 | F15: =SUM(F7:F14) -> 11671 | G15: =SUM(G7:G14) -> 31698 | H15: =SUM(H7:H14) -> 28907 | I15: =SUM(I7:I14) -> 3532 | J15: =SUM(J7:J14) -> 32261 | K15: =SUM(K7:K14) -> 75240 | ... M15: =SUM(M7:M14) -> 4003
B17: Fixed assets purchased | D17: =IFERROR(Sheet1!E13,0) -> -16072 | E17: =IFERROR(Sheet1!F13,0) -> -35079 | F17: =IFERROR(Sheet1!G13,0) -> -35304 | G17: =IFERROR(Sheet1!H13,0) -> -29702 | H17: =IFERROR(Sheet1!I13,0) -> -20205 | I17: =IFERROR(Sheet1!J13,0) -> -15168 | J17: =IFERROR(Sheet1!K13,0) -> -19230 | K17: =IFERROR(Sheet1!L13,0) -> -31414 | ... M17: =IFERROR(Sheet1!N13,0) -> -36282
B18: Fixed assets sold | D18: =IFERROR(Sheet1!E14,0) -> 53 | E18: =IFERROR(Sheet1!F14,0) -> 30 | F18: =IFERROR(Sheet1!G14,0) -> 67 | G18: =IFERROR(Sheet1!H14,0) -> 171 | H18: =IFERROR(Sheet1!I14,0) -> 351 | I18: =IFERROR(Sheet1!J14,0) -> 230 | J18: =IFERROR(Sheet1!K14,0) -> 285 | K18: =IFERROR(Sheet1!L14,0) -> 231 | ... M18: =IFERROR(Sheet1!N14,0) -> 46
B19: Investments purchased | D19: =IFERROR(Sheet1!E15,0) -> -6 | E19: =IFERROR(Sheet1!F15,0) -> -329 | F19: =IFERROR(Sheet1!G15,0) -> -130 | G19: =IFERROR(Sheet1!H15,0) -> -1439 | H19: =IFERROR(Sheet1!I15,0) -> -7530 | I19: =IFERROR(Sheet1!J15,0) -> -3008 | J19: =IFERROR(Sheet1!K15,0) -> -50 | K19: =IFERROR(Sheet1!L15,0) -> -74 | ... M19: =IFERROR(Sheet1!N15,0) -> -102
B20: Investments sold | D20: =IFERROR(Sheet1!E16,0) -> 1965 | E20: =IFERROR(Sheet1!F16,0) -> 2381 | F20: =IFERROR(Sheet1!G16,0) -> 5644 | G20: =IFERROR(Sheet1!H16,0) -> 21 | H20: =IFERROR(Sheet1!I16,0) -> 226 | I20: =IFERROR(Sheet1!J16,0) -> 104 | J20: =IFERROR(Sheet1!K16,0) -> 6895 | K20: =IFERROR(Sheet1!L16,0) -> 10821 | ... M20: =IFERROR(Sheet1!N16,0) -> 10684
B21: Interest received | D21: =IFERROR(Sheet1!E17,0) -> 638 | E21: =IFERROR(Sheet1!F17,0) -> 690 | F21: =IFERROR(Sheet1!G17,0) -> 761 | G21: =IFERROR(Sheet1!H17,0) -> 1104 | H21: =IFERROR(Sheet1!I17,0) -> 428 | I21: =IFERROR(Sheet1!J17,0) -> 653 | J21: =IFERROR(Sheet1!K17,0) -> 973 | K21: =IFERROR(Sheet1!L17,0) -> 2493 | ... M21: =IFERROR(Sheet1!N17,0) -> 1940
B22: Dividends received | D22: =IFERROR(Sheet1!E18,0) -> 620 | E22: =IFERROR(Sheet1!F18,0) -> 1797 | F22: =IFERROR(Sheet1!G18,0) -> 232 | G22: =IFERROR(Sheet1!H18,0) -> 21 | H22: =IFERROR(Sheet1!I18,0) -> 18 | I22: =IFERROR(Sheet1!J18,0) -> 32 | J22: =IFERROR(Sheet1!K18,0) -> 46 | K22: =IFERROR(Sheet1!L18,0) -> 47 | ... M22: =IFERROR(Sheet1!N18,0) -> 100
B23: Acquisition of companies | D23: =IFERROR(Sheet1!E19,0) -> -107 | E23: =IFERROR(Sheet1!F19,0) -> -4 | F23: =IFERROR(Sheet1!G19,0) -> -9 | G23: =IFERROR(Sheet1!H19,0) -> -606 | H23: =IFERROR(Sheet1!I19,0) -> -10 | I23: =IFERROR(Sheet1!J19,0) -> 0 | J23: =IFERROR(Sheet1!K19,0) -> 0 | K23: =IFERROR(Sheet1!L19,0) -> -150 | ... M23: =IFERROR(Sheet1!N19,0) -> -5
B24: Other investing items | D24: =IFERROR(Sheet1!E20,0) -> 0 | E24: =IFERROR(Sheet1!F20,0) -> 14 | F24: =IFERROR(Sheet1!G20,0) -> 533 | G24: =IFERROR(Sheet1!H20,0) -> 0 | H24: =IFERROR(Sheet1!I20,0) -> 0 | I24: =IFERROR(Sheet1!J20,0) -> 0 | J24: =IFERROR(Sheet1!K20,0) -> 19 | K24: =IFERROR(Sheet1!L20,0) -> 107 | ... M24: =IFERROR(Sheet1!N20,0) -> 20
B25: Cash from Investing Activities | D25: =SUM(D17:D24) -> -12909 | E25: =SUM(E17:E24) -> -30500 | F25: =SUM(F17:F24) -> -28206 | G25: =SUM(G17:G24) -> -30430 | H25: =SUM(H17:H24) -> -26722 | I25: =SUM(I17:I24) -> -17157 | J25: =SUM(J17:J24) -> -11062 | K25: =SUM(K17:K24) -> -17939 | ... M25: =SUM(M17:M24) -> -23599
B27: Proceeds from borrowings | D27: =IFERROR(Sheet1!E25,0) -> 5 | E27: =IFERROR(Sheet1!F25,0) -> 0 | F27: =IFERROR(Sheet1!G25,0) -> 0 | G27: =IFERROR(Sheet1!H25,0) -> 3889 | H27: =IFERROR(Sheet1!I25,0) -> 2603 | I27: =IFERROR(Sheet1!J25,0) -> 19 | J27: =IFERROR(Sheet1!K25,0) -> 20 | K27: =IFERROR(Sheet1!L25,0) -> 82 | ... M27: =IFERROR(Sheet1!N25,0) -> 18
B28: Repayment of borrowings | D28: =IFERROR(Sheet1!E26,0) -> 0 | E28: =IFERROR(Sheet1!F26,0) -> 0 | F28: =IFERROR(Sheet1!G26,0) -> 0 | G28: =IFERROR(Sheet1!H26,0) -> 0 | H28: =IFERROR(Sheet1!I26,0) -> 0 | I28: =IFERROR(Sheet1!J26,0) -> 0 | J28: =IFERROR(Sheet1!K26,0) -> 0 | K28: =IFERROR(Sheet1!L26,0) -> 0 | ... M28: =IFERROR(Sheet1!N26,0) -> 0
B29: Investment subsidy | D29: =IFERROR(Sheet1!E27,0) -> 33390 | E29: =IFERROR(Sheet1!F27,0) -> 37482 | F29: =IFERROR(Sheet1!G27,0) -> 51128 | G29: =IFERROR(Sheet1!H27,0) -> 38297 | H29: =IFERROR(Sheet1!I27,0) -> 46641 | I29: =IFERROR(Sheet1!J27,0) -> 46578 | J29: =IFERROR(Sheet1!K27,0) -> 43934 | K29: =IFERROR(Sheet1!L27,0) -> 18829 | ... M29: =IFERROR(Sheet1!N27,0) -> 26425
B30: Interest paid fin | D30: =IFERROR(Sheet1!E28,0) -> -21732 | E30: =IFERROR(Sheet1!F28,0) -> -29964 | F30: =IFERROR(Sheet1!G28,0) -> -35198 | G30: =IFERROR(Sheet1!H28,0) -> -29847 | H30: =IFERROR(Sheet1!I28,0) -> -29709 | I30: =IFERROR(Sheet1!J28,0) -> -42816 | J30: =IFERROR(Sheet1!K28,0) -> -62557 | K30: =IFERROR(Sheet1!L28,0) -> -47414 | ... M30: =IFERROR(Sheet1!N28,0) -> -18110
B31: Dividends paid | D31: =IFERROR(Sheet1!E29,0) -> -5336 | E31: =IFERROR(Sheet1!F29,0) -> -5411 | F31: =IFERROR(Sheet1!G29,0) -> -7005 | G31: =IFERROR(Sheet1!H29,0) -> -7518 | H31: =IFERROR(Sheet1!I29,0) -> -8123 | I31: =IFERROR(Sheet1!J29,0) -> -9251 | J31: =IFERROR(Sheet1!K29,0) -> -9336 | K31: =IFERROR(Sheet1!L29,0) -> -9332 | ... M31: =IFERROR(Sheet1!N29,0) -> -5111
B32: Financial liabilities | D32: =IFERROR(Sheet1!E30,0) -> -121 | E32: =IFERROR(Sheet1!F30,0) -> -96 | F32: =IFERROR(Sheet1!G30,0) -> -95 | G32: =IFERROR(Sheet1!H30,0) -> -57 | H32: =IFERROR(Sheet1!I30,0) -> -30 | I32: =IFERROR(Sheet1!J30,0) -> -100 | J32: =IFERROR(Sheet1!K30,0) -> -141 | K32: =IFERROR(Sheet1!L30,0) -> -1059 | ... M32: =IFERROR(Sheet1!N30,0) -> -2425
B33: Other financing items | D33: =IFERROR(Sheet1!E31,0) -> 0 | E33: =IFERROR(Sheet1!F31,0) -> 0 | F33: =IFERROR(Sheet1!G31,0) -> 0 | G33: =IFERROR(Sheet1!H31,0) -> -1346 | H33: =IFERROR(Sheet1!I31,0) -> -1477 | I33: =IFERROR(Sheet1!J31,0) -> -1559 | J33: =IFERROR(Sheet1!K31,0) -> -1517 | K33: =IFERROR(Sheet1!L31,0) -> -1924 | ... M33: =IFERROR(Sheet1!N31,0) -> -2145
B34: Cash from Financial Activities | D34: =SUM(D27:D33) -> 6206 | E34: =SUM(E27:E33) -> 2011 | F34: =SUM(F27:F33) -> 8830 | G34: =SUM(G27:G33) -> 3418 | H34: =SUM(H27:H33) -> 9905 | I34: =SUM(I27:I33) -> -7129 | J34: =SUM(J27:J33) -> -29597 | K34: =SUM(K27:K33) -> -40818 | ... M34: =SUM(M27:M33) -> -1348

Sheet Ratio Analysis
B2: ="Ratio Analysis "&'Data Sheet'!B1 -> Ratio Analysis TATA MOTORS PASSENGER VEHICLES LTD
B3: Particulars | C3: ='Cash Flow Statement'!D3 -> 42825 | D3: ='Cash Flow Statement'!E3 -> 43190 | E3: ='Cash Flow Statement'!F3 -> 43555 | F3: ='Cash Flow Statement'!G3 -> 43921 | G3: ='Cash Flow Statement'!H3 -> 44286 | H3: ='Cash Flow Statement'!I3 -> 44651 | I3: ='Cash Flow Statement'!J3 -> 45016 | J3: ='Cash Flow Statement'!K3 -> 45382 | ... L3: ='Cash Flow Statement'!M3 -> 46112 | M3: Trend | N3: Mean | O3: Median
A5: # | B5: Profitability Ratio:
B7: Sales Growth | D7: =IFERROR('Income Statement'!E8,0) -> 0.081047746 | E7: =IFERROR('Income Statement'!F8,0) -> 0.035629919 | F7: =IFERROR('Income Statement'!G8,0) -> -0.13536016 | G7: =IFERROR('Income Statement'!H8,0) -> -0.043181168 | H7: =IFERROR('Income Statement'!I8,0) -> 0.11472967 | I7: =IFERROR('Income Statement'!J8,0) -> 0.24245815 | J7: =IFERROR('Income Statement'!K8,0) -> 0.25450126 | K7: =IFERROR('Income Statement'!L8,0) -> -0.15649653 | L7: =IFERROR('Income Statement'!M8,0) -> -0.083344715 | N7: =AVERAGE(D7:L7) -> 0.034442686 | O7: =MEDIAN(D7:L7) -> 0.035629919
B8: EBITDA Growth | D8: =IFERROR('Income Statement'!E19/'Income Statement'!D19-1,0) -> 0.063165689 | E8: =IFERROR('Income Statement'!F19/'Income Statement'!E19-1,0) -> -0.21595203 | F8: =IFERROR('Income Statement'!G19/'Income Statement'!F19-1,0) -> -0.27072538 | G8: =IFERROR('Income Statement'!H19/'Income Statement'!G19-1,0) -> 0.70224556 | H8: =IFERROR('Income Statement'!I19/'Income Statement'!H19-1,0) -> -0.19263966 | I8: =IFERROR('Income Statement'!J19/'Income Statement'!I19-1,0) -> 0.28704224 | J8: =IFERROR('Income Statement'!K19/'Income Statement'!J19-1,0) -> 0.75802589 | K8: =IFERROR('Income Statement'!L19/'Income Statement'!K19-1,0) -> -0.38742782 | L8: =IFERROR('Income Statement'!M19/'Income Statement'!L19-1,0) -> -1.0777807 | N8: =AVERAGE(D8:L8) -> -0.037116245 | O8: =MEDIAN(D8:L8) -> -0.19263966
B9: EBIT Growth | D9: =IFERROR('Income Statement'!E27/'Income Statement'!D27-1,0) -> 0.16852754 | E9: =IFERROR('Income Statement'!F27/'Income Statement'!E27-1,0) -> -2.6172786 | F9: =IFERROR('Income Statement'!G27/'Income Statement'!F27-1,0) -> -0.86972597 | G9: =IFERROR('Income Statement'!H27/'Income Statement'!G27-1,0) -> 0.21263243 | H9: =IFERROR('Income Statement'!I27/'Income Statement'!H27-1,0) -> -1.5705328 | I9: =IFERROR('Income Statement'!J27/'Income Statement'!I27-1,0) -> 4.8998072 | J9: =IFERROR('Income Statement'!K27/'Income Statement'!J27-1,0) -> 1.4597982 | K9: =IFERROR('Income Statement'!L27/'Income Statement'!K27-1,0) -> -0.18271096 | L9: =IFERROR('Income Statement'!M27/'Income Statement'!L27-1,0) -> 1.331702 | N9: =AVERAGE(D9:L9) -> 0.314691 | O9: =MEDIAN(D9:L9) -> 0.16852754
B10: PAT Growth | D10: =IFERROR('Income Statement'!E38/'Income Statement'!D38-1,0) -> 0.12361385 | E10: =IFERROR('Income Statement'!F38/'Income Statement'!E38-1,0) -> -5.2467746 | F10: =IFERROR('Income Statement'!G38/'Income Statement'!F38-1,0) -> -0.62067658 | G10: =IFERROR('Income Statement'!H38/'Income Statement'!G38-1,0) -> 0.33802754 | H10: =IFERROR('Income Statement'!I38/'Income Statement'!H38-1,0) -> -0.23496237 | I10: =IFERROR('Income Statement'!J38/'Income Statement'!I38-1,0) -> -1.2394252 | J10: =IFERROR('Income Statement'!K38/'Income Statement'!J38-1,0) -> 10.127304 | K10: =IFERROR('Income Statement'!L38/'Income Statement'!K38-1,0) -> -0.51825866 | L10: =IFERROR('Income Statement'!M38/'Income Statement'!L38-1,0) -> 3.2486303 | N10: =AVERAGE(D10:L10) -> 0.6641642 | O10: =MEDIAN(D10:L10) -> -0.23496237
B11: EBITDA Margin | C11: =IFERROR('Income Statement'!D20,0) -> 0.10971269 | D11: =IFERROR('Income Statement'!E20,0) -> 0.10789788 | E11: =IFERROR('Income Statement'!F20,0) -> 0.081686629 | F11: =IFERROR('Income Statement'!G20,0) -> 0.068898034 | G11: =IFERROR('Income Statement'!H20,0) -> 0.12257427 | H11: =IFERROR('Income Statement'!I20,0) -> 0.088776328 | I11: =IFERROR('Income Statement'!J20,0) -> 0.091961958 | J11: =IFERROR('Income Statement'!K20,0) -> 0.12887313 | ... L11: =IFERROR('Income Statement'!M20,0) -> -0.0079414271 | N11: =AVERAGE(C11:L11) -> 0.088603021 | O11: =MEDIAN(C11:L11) -> 0.092776338
B12: PAT Margin | C12: =IFERROR('Income Statement'!D39,0) -> 0.022483235 | D12: =IFERROR('Income Statement'!E39,0) -> 0.023368509 | E12: =IFERROR('Income Statement'!F39,0) -> -0.0958265 | F12: =IFERROR('Income Statement'!G39,0) -> -0.042039742 | G12: =IFERROR('Income Statement'!H39,0) -> -0.058788906 | H12: =IFERROR('Income Statement'!I39,0) -> -0.040346755 | I12: =IFERROR('Income Statement'!J39,0) -> 0.007774933 | J12: =IFERROR('Income Statement'!K39,0) -> 0.068962895 | ... L12: =IFERROR('Income Statement'!M39,0) -> 0.18255151 | N12: =AVERAGE(C12:L12) -> 0.010752524 | O12: =MEDIAN(C12:L12) -> 0.015129084
B13: ROE | C13: =IFERROR('Income Statement'!D38/SUM('Balance Sheet'!D8:D9),0) -> 0.1044327 | D13: =IFERROR('Income Statement'!E38/SUM('Balance Sheet'!E8:E9),0) -> 0.071395255 | E13: =IFERROR('Income Statement'!F38/SUM('Balance Sheet'!F8:F9),0) -> -0.48078949 | F13: =IFERROR('Income Statement'!G38/SUM('Balance Sheet'!G8:G9),0) -> -0.17399312 | G13: =IFERROR('Income Statement'!H38/SUM('Balance Sheet'!H8:H9),0) -> -0.26581053 | H13: =IFERROR('Income Statement'!I38/SUM('Balance Sheet'!I8:I9),0) -> -0.25211821 | I13: =IFERROR('Income Statement'!J38/SUM('Balance Sheet'!J8:J9),0) -> 0.05935048 | J13: =IFERROR('Income Statement'!K38/SUM('Balance Sheet'!K8:K9),0) -> 0.35246944 | ... L13: =IFERROR('Income Statement'!M38/SUM('Balance Sheet'!M8:M9),0) -> 0.54664132 | N13: =AVERAGE(C13:L13) -> 0.0085725466 | O13: =MEDIAN(C13:L13) -> 0.065372868
B14: ROCE | C14: =IFERROR('Income Statement'!D27/SUM('Balance Sheet'!D8:D9,'Balance Sheet'!D10),0) -> 0.099167407 | D14: =IFERROR('Income Statement'!E27/SUM('Balance Sheet'!E8:E9,'Balance Sheet'!E10),0) -> 0.085893042 | E14: =IFERROR('Income Statement'!F27/SUM('Balance Sheet'!F8:F9,'Balance Sheet'!F10),0) -> -0.1539633 | F14: =IFERROR('Income Statement'!G27/SUM('Balance Sheet'!G8:G9,'Balance Sheet'!G10),0) -> -0.017760782 | G14: =IFERROR('Income Statement'!H27/SUM('Balance Sheet'!H8:H9,'Balance Sheet'!H10),0) -> -0.020499471 | H14: =IFERROR('Income Statement'!I27/SUM('Balance Sheet'!I8:I9,'Balance Sheet'!I10),0) -> 0.012085476 | I14: =IFERROR('Income Statement'!J27/SUM('Balance Sheet'!J8:J9,'Balance Sheet'!J10),0) -> 0.075901538 | J14: =IFERROR('Income Statement'!K27/SUM('Balance Sheet'!K8:K9,'Balance Sheet'!K10),0) -> 0.17431913 | ... L14: =IFERROR('Income Statement'!M27/SUM('Balance Sheet'!M8:M9,'Balance Sheet'!M10),0) -> 0.33394184 | N14: =AVERAGE(C14:L14) -> 0.073496839 | O14: =MEDIAN(C14:L14) -> 0.08089729
B15: ROA | C15: =IFERROR('Income Statement'!D38/'Balance Sheet'!D18,0) -> 0.032366326 | D15: =IFERROR('Income Statement'!E38/'Balance Sheet'!E18,0) -> 0.029551896 | E15: =IFERROR('Income Statement'!F38/'Balance Sheet'!F18,0) -> -0.13454733 | F15: =IFERROR('Income Statement'!G38/'Balance Sheet'!G18,0) -> -0.046148762 | G15: =IFERROR('Income Statement'!H38/'Balance Sheet'!H18,0) -> -0.059693399 | H15: =IFERROR('Income Statement'!I38/'Balance Sheet'!I18,0) -> -0.046673206 | I15: =IFERROR('Income Statement'!J38/'Balance Sheet'!J18,0) -> 0.011153626 | J15: =IFERROR('Income Statement'!K38/'Balance Sheet'!K18,0) -> 0.11557531 | ... L15: =IFERROR('Income Statement'!M38/'Balance Sheet'!M18,0) -> 0.21363161 | N15: =AVERAGE(C15:L15) -> 0.016753047 | O15: =MEDIAN(C15:L15) -> 0.020352761
A18: # | B18: Levarage/Solvency Ratio:
B20: Interest Coverage Ratio | C20: =IFERROR('Income Statement'!D27/'Balance Sheet'!D10,0) -> 0.17241875 | D20: =IFERROR('Income Statement'!E27/'Balance Sheet'!E10,0) -> 0.17804088 | E20: =IFERROR('Income Statement'!F27/'Balance Sheet'!F10,0) -> -0.2412288 | F20: =IFERROR('Income Statement'!G27/'Balance Sheet'!G10,0) -> -0.026738626 | G20: =IFERROR('Income Statement'!H27/'Balance Sheet'!H10,0) -> -0.028467697 | H20: =IFERROR('Income Statement'!I27/'Balance Sheet'!I10,0) -> 0.015762822 | I20: =IFERROR('Income Statement'!J27/'Balance Sheet'!J10,0) -> 0.10155142 | J20: =IFERROR('Income Statement'!K27/'Balance Sheet'!K10,0) -> 0.31232287 | ... L20: =IFERROR('Income Statement'!M27/'Balance Sheet'!M10,0) -> 0.80701311 | N20: =AVERAGE(C20:L20) -> 0.16733977 | O20: =MEDIAN(C20:L20) -> 0.13698508
B21: Debt to Equity | C21: =IFERROR('Balance Sheet'!D10/SUM('Balance Sheet'!D8:D9),0) -> 1.3537964 | D21: =IFERROR('Balance Sheet'!E10/SUM('Balance Sheet'!E8:E9),0) -> 0.93212216 | E21: =IFERROR('Balance Sheet'!F10/SUM('Balance Sheet'!F8:F9),0) -> 1.764309 | F21: =IFERROR('Balance Sheet'!G10/SUM('Balance Sheet'!G8:G9),0) -> 1.9782902 | G21: =IFERROR('Balance Sheet'!H10/SUM('Balance Sheet'!H8:H9),0) -> 2.5726517 | H21: =IFERROR('Balance Sheet'!I10/SUM('Balance Sheet'!I8:I9),0) -> 3.2864667 | I21: =IFERROR('Balance Sheet'!J10/SUM('Balance Sheet'!J8:J9),0) -> 2.9591382 | J21: =IFERROR('Balance Sheet'!K10/SUM('Balance Sheet'!K8:K9),0) -> 1.263148 | ... L21: =IFERROR('Balance Sheet'!M10/SUM('Balance Sheet'!M8:M9),0) -> 0.70590177 | N21: =AVERAGE(C21:L21) -> 1.7431784 | O21: =MEDIAN(C21:L21) -> 1.5590527
B22: Debt to Assets | C22: =IFERROR('Balance Sheet'!D10/SUM('Balance Sheet'!D14,'Balance Sheet'!D17),0) -> 0.58965577 | D22: =IFERROR('Balance Sheet'!E10/SUM('Balance Sheet'!E14,'Balance Sheet'!E17),0) -> 0.52416083 | E22: =IFERROR('Balance Sheet'!F10/SUM('Balance Sheet'!F14,'Balance Sheet'!F17),0) -> 0.63429839 | F22: =IFERROR('Balance Sheet'!G10/SUM('Balance Sheet'!G14,'Balance Sheet'!G17),0) -> 0.67129078 | G22: =IFERROR('Balance Sheet'!H10/SUM('Balance Sheet'!H14,'Balance Sheet'!H17),0) -> 0.7091439 | H22: =IFERROR('Balance Sheet'!I10/SUM('Balance Sheet'!I14,'Balance Sheet'!I17),0) -> 0.72831509 | I22: =IFERROR('Balance Sheet'!J10/SUM('Balance Sheet'!J14,'Balance Sheet'!J17),0) -> 0.66885543 | J22: =IFERROR('Balance Sheet'!K10/SUM('Balance Sheet'!K14,'Balance Sheet'!K17),0) -> 0.53550336 | ... L22: =IFERROR('Balance Sheet'!M10/SUM('Balance Sheet'!M14,'Balance Sheet'!M17),0) -> 0.5013467 | N22: =AVERAGE(C22:L22) -> 0.5973342 | O22: =MEDIAN(C22:L22) -> 0.61197708
B23: Financial Levarage Ratio | C23: =IFERROR(SUM('Balance Sheet'!D14,'Balance Sheet'!D17)/SUM('Balance Sheet'!D8:D9),0) -> 2.2959098 | D23: =IFERROR(SUM('Balance Sheet'!E14,'Balance Sheet'!E17)/SUM('Balance Sheet'!E8:E9),0) -> 1.7783133 | E23: =IFERROR(SUM('Balance Sheet'!F14,'Balance Sheet'!F17)/SUM('Balance Sheet'!F8:F9),0) -> 2.7815127 | F23: =IFERROR(SUM('Balance Sheet'!G14,'Balance Sheet'!G17)/SUM('Balance Sheet'!G8:G9),0) -> 2.9469945 | G23: =IFERROR(SUM('Balance Sheet'!H14,'Balance Sheet'!H17)/SUM('Balance Sheet'!H8:H9),0) -> 3.6278275 | H23: =IFERROR(SUM('Balance Sheet'!I14,'Balance Sheet'!I17)/SUM('Balance Sheet'!I8:I9),0) -> 4.5124243 | I23: =IFERROR(SUM('Balance Sheet'!J14,'Balance Sheet'!J17)/SUM('Balance Sheet'!J8:J9),0) -> 4.4241821 | J23: =IFERROR(SUM('Balance Sheet'!K14,'Balance Sheet'!K17)/SUM('Balance Sheet'!K8:K9),0) -> 2.358805 | ... L23: =IFERROR(SUM('Balance Sheet'!M14,'Balance Sheet'!M17)/SUM('Balance Sheet'!M8:M9),0) -> 1.4080112 | N23: =AVERAGE(C23:L23) -> 2.7633498 | O23: =MEDIAN(C23:L23) -> 2.5701588
A27: # | B27: Operating/ Management Ratio:
B29: Fixed Assets Turnover Ratio | C29: ='Income Statement'!D27/'Balance Sheet'!D14 -> 0.14125728 | D29: ='Income Statement'!E27/'Balance Sheet'!E14 -> 0.13043667 | E29: ='Income Statement'!F27/'Balance Sheet'!F14 -> -0.23025731 | F29: ='Income Statement'!G27/'Balance Sheet'!G14 -> -0.026250689 | G29: ='Income Statement'!H27/'Balance Sheet'!H14 -> -0.029170209 | H29: ='Income Statement'!I27/'Balance Sheet'!I14 -> 0.016624843 | I29: ='Income Statement'!J27/'Balance Sheet'!J14 -> 0.10311504 | J29: ='Income Statement'!K27/'Balance Sheet'!K14 -> 0.27621717 | ... L29: ='Income Statement'!M27/'Balance Sheet'!M14 -> 0.61001758 | N29: =AVERAGE(C29:L29) -> 0.1228643 | O29: =MEDIAN(C29:L29) -> 0.11677586
B30: Total Assets Turnover Ratio | C30: =IFERROR('Income Statement'!D27/SUM('Balance Sheet'!D14,'Balance Sheet'!D17),0) -> 0.10166771 | D30: =IFERROR('Income Statement'!E27/SUM('Balance Sheet'!E14,'Balance Sheet'!E17),0) -> 0.093322055 | E30: =IFERROR('Income Statement'!F27/SUM('Balance Sheet'!F14,'Balance Sheet'!F17),0) -> -0.15301104 | F30: =IFERROR('Income Statement'!G27/SUM('Balance Sheet'!G14,'Balance Sheet'!G17),0) -> -0.017949393 | G30: =IFERROR('Income Statement'!H27/SUM('Balance Sheet'!H14,'Balance Sheet'!H17),0) -> -0.020187694 | H30: =IFERROR('Income Statement'!I27/SUM('Balance Sheet'!I14,'Balance Sheet'!I17),0) -> 0.011480301 | I30: =IFERROR('Income Statement'!J27/SUM('Balance Sheet'!J14,'Balance Sheet'!J17),0) -> 0.067923218 | J30: =IFERROR('Income Statement'!K27/SUM('Balance Sheet'!K14,'Balance Sheet'!K17),0) -> 0.16724994 | ... L30: =IFERROR('Income Statement'!M27/SUM('Balance Sheet'!M14,'Balance Sheet'!M17),0) -> 0.40459336 | N30: =AVERAGE(C30:L30) -> 0.081230022 | O30: =MEDIAN(C30:L30) -> 0.080622636
B31: Capital Turnover Ratio | C31: =IFERROR('Income Statement'!D38/SUM('Balance Sheet'!D8:D9),0) -> 0.1044327 | D31: =IFERROR('Income Statement'!E38/SUM('Balance Sheet'!E8:E9),0) -> 0.071395255 | E31: =IFERROR('Income Statement'!F38/SUM('Balance Sheet'!F8:F9),0) -> -0.48078949 | F31: =IFERROR('Income Statement'!G38/SUM('Balance Sheet'!G8:G9),0) -> -0.17399312 | G31: =IFERROR('Income Statement'!H38/SUM('Balance Sheet'!H8:H9),0) -> -0.26581053 | H31: =IFERROR('Income Statement'!I38/SUM('Balance Sheet'!I8:I9),0) -> -0.25211821 | I31: =IFERROR('Income Statement'!J38/SUM('Balance Sheet'!J8:J9),0) -> 0.05935048 | J31: =IFERROR('Income Statement'!K38/SUM('Balance Sheet'!K8:K9),0) -> 0.35246944 | ... L31: =IFERROR('Income Statement'!M38/SUM('Balance Sheet'!M8:M9),0) -> 0.54664132 | N31: =AVERAGE(C31:L31) -> 0.0085725466 | O31: =MEDIAN(C31:L31) -> 0.065372868
B32: Debtors Turnover Ratio | C32: =IFERROR('Income Statement'!D7/'Balance Sheet'!D20,0) -> 19.160353 | D32: =IFERROR('Income Statement'!E7/'Balance Sheet'!E20,0) -> 14.655712 | E32: =IFERROR('Income Statement'!F7/'Balance Sheet'!F20,0) -> 15.894699 | F32: =IFERROR('Income Statement'!G7/'Balance Sheet'!G20,0) -> 23.366617 | G32: =IFERROR('Income Statement'!H7/'Balance Sheet'!H20,0) -> 19.701331 | H32: =IFERROR('Income Statement'!I7/'Balance Sheet'!I20,0) -> 22.379918 | I32: =IFERROR('Income Statement'!J7/'Balance Sheet'!J20,0) -> 21.982948 | J32: =IFERROR('Income Statement'!K7/'Balance Sheet'!K20,0) -> 25.602643 | ... L32: =IFERROR('Income Statement'!M7/'Balance Sheet'!M20,0) -> 26.593391 | N32: =AVERAGE(C32:L32) -> 21.697152 | O32: =MEDIAN(C32:L32) -> 22.181433
B33: Inventory Turnover Ratio | C33: =IFERROR('Income Statement'!D9/'Balance Sheet'!D21,0) -> 5.8558479 | D33: =IFERROR('Income Statement'!E9/'Balance Sheet'!E21,0) -> 5.4210412 | E33: =IFERROR('Income Statement'!F9/'Balance Sheet'!F21,0) -> 6.2246171 | F33: =IFERROR('Income Statement'!G9/'Balance Sheet'!G21,0) -> 5.6164867 | G33: =IFERROR('Income Statement'!H9/'Balance Sheet'!H21,0) -> 5.4124043 | H33: =IFERROR('Income Statement'!I9/'Balance Sheet'!I21,0) -> 6.3364885 | I33: =IFERROR('Income Statement'!J9/'Balance Sheet'!J21,0) -> 6.7329411 | J33: =IFERROR('Income Statement'!K9/'Balance Sheet'!K21,0) -> 6.9971541 | ... L33: =IFERROR('Income Statement'!M9/'Balance Sheet'!M21,0) -> 5.5454854 | N33: =AVERAGE(C33:L33) -> 6.0109548 | O33: =MEDIAN(C33:L33) -> 5.911465
B34: Creditors Turnover Ratio | C34: =IFERROR('Income Statement'!D9/'Balance Sheet'!D11,0) -> 1.5116434 | D34: =IFERROR('Income Statement'!E9/'Balance Sheet'!E11,0) -> 1.5994982 | E34: =IFERROR('Income Statement'!F9/'Balance Sheet'!F11,0) -> 1.7427197 | F34: =IFERROR('Income Statement'!G9/'Balance Sheet'!G11,0) -> 1.5899853 | G34: =IFERROR('Income Statement'!H9/'Balance Sheet'!H11,0) -> 1.3546188 | H34: =IFERROR('Income Statement'!I9/'Balance Sheet'!I11,0) -> 1.6175157 | I34: =IFERROR('Income Statement'!J9/'Balance Sheet'!J11,0) -> 1.7676182 | J34: =IFERROR('Income Statement'!K9/'Balance Sheet'!K11,0) -> 1.8855413 | ... L34: =IFERROR('Income Statement'!M9/'Balance Sheet'!M11,0) -> 1.4784854 | N34: =AVERAGE(C34:L34) -> 1.6037718 | O34: =MEDIAN(C34:L34) -> 1.5947418
B36: Cash Conversion Cycle: Days | C36: 365
B38: DIO | C38: ='Balance Sheet'!D21/'Income Statement'!D9*'Ratio Analysis'!$C$36 -> 62.330854 | D38: ='Balance Sheet'!E21/'Income Statement'!E9*'Ratio Analysis'!$C$36 -> 67.330239 | E38: ='Balance Sheet'!F21/'Income Statement'!F9*'Ratio Analysis'!$C$36 -> 58.638145 | F38: ='Balance Sheet'!G21/'Income Statement'!G9*'Ratio Analysis'!$C$36 -> 64.987245 | G38: ='Balance Sheet'!H21/'Income Statement'!H9*'Ratio Analysis'!$C$36 -> 67.437682 | H38: ='Balance Sheet'!I21/'Income Statement'!I9*'Ratio Analysis'!$C$36 -> 57.602882 | I38: ='Balance Sheet'!J21/'Income Statement'!J9*'Ratio Analysis'!$C$36 -> 54.211079 | J38: ='Balance Sheet'!K21/'Income Statement'!K9*'Ratio Analysis'!$C$36 -> 52.164065 | ... L38: ='Balance Sheet'!M21/'Income Statement'!M9*'Ratio Analysis'!$C$36 -> 65.819306 | N38: =AVERAGE(C38:L38) -> 61.169042 | O38: =MEDIAN(C38:L38) -> 61.74989
B39: DSO | C39: ='Balance Sheet'!D20/'Income Statement'!D7*'Ratio Analysis'!$C$36 -> 19.049753 | D39: ='Balance Sheet'!E20/'Income Statement'!E7*'Ratio Analysis'!$C$36 -> 24.904965 | E39: ='Balance Sheet'!F20/'Income Statement'!F7*'Ratio Analysis'!$C$36 -> 22.963631 | F39: ='Balance Sheet'!G20/'Income Statement'!G7*'Ratio Analysis'!$C$36 -> 15.620575 | G39: ='Balance Sheet'!H20/'Income Statement'!H7*'Ratio Analysis'!$C$36 -> 18.526667 | H39: ='Balance Sheet'!I20/'Income Statement'!I7*'Ratio Analysis'!$C$36 -> 16.309265 | I39: ='Balance Sheet'!J20/'Income Statement'!J7*'Ratio Analysis'!$C$36 -> 16.603779 | J39: ='Balance Sheet'!K20/'Income Statement'!K7*'Ratio Analysis'!$C$36 -> 14.256341 | ... L39: ='Balance Sheet'!M20/'Income Statement'!M7*'Ratio Analysis'!$C$36 -> 13.725215 | N39: =AVERAGE(C39:L39) -> 17.51686 | O39: =MEDIAN(C39:L39) -> 16.456522
B40: DPO | C40: ='Balance Sheet'!D11/'Income Statement'!D9*'Ratio Analysis'!$C$36 -> 241.45907 | D40: ='Balance Sheet'!E11/'Income Statement'!E9*'Ratio Analysis'!$C$36 -> 228.19656 | E40: ='Balance Sheet'!F11/'Income Statement'!F9*'Ratio Analysis'!$C$36 -> 209.44275 | F40: ='Balance Sheet'!G11/'Income Statement'!G9*'Ratio Analysis'!$C$36 -> 229.56188 | G40: ='Balance Sheet'!H11/'Income Statement'!H9*'Ratio Analysis'!$C$36 -> 269.44849 | H40: ='Balance Sheet'!I11/'Income Statement'!I9*'Ratio Analysis'!$C$36 -> 225.65469 | I40: ='Balance Sheet'!J11/'Income Statement'!J9*'Ratio Analysis'!$C$36 -> 206.49255 | J40: ='Balance Sheet'!K11/'Income Statement'!K9*'Ratio Analysis'!$C$36 -> 193.57837 | ... L40: ='Balance Sheet'!M11/'Income Statement'!M9*'Ratio Analysis'!$C$36 -> 246.87426 | N40: =AVERAGE(C40:L40) -> 229.566 | O40: =MEDIAN(C40:L40) -> 228.87922
B42: Cash Conversion Cycle | C42: =C38+C39-C40 -> -160.07846 | D42: =D38+D39-D40 -> -135.96136 | E42: =E38+E39-E40 -> -127.84097 | F42: =F38+F39-F40 -> -148.95406 | G42: =G38+G39-G40 -> -183.48414 | H42: =H38+H39-H40 -> -151.74255 | I42: =I38+I39-I40 -> -135.67769 | J42: =J38+J39-J40 -> -127.15796 | ... L42: =L38+L39-L40 -> -167.32974 | N42: =AVERAGE(C42:L42) -> -150.88009 | O42: =MEDIAN(C42:L42) -> -150.3483
A45: # | B45: Valuation Ratio: | C45: ='Data Sheet'!B8 -> 334.5
B47: No.of shares | C47: ='Income Statement'!D41 -> 288.73 | D47: ='Income Statement'!E41 -> 288.73 | E47: ='Income Statement'!F41 -> 288.73 | F47: ='Income Statement'!G41 -> 308.9 | G47: ='Income Statement'!H41 -> 332.03 | H47: ='Income Statement'!I41 -> 332.07 | I47: ='Income Statement'!J41 -> 332.13 | J47: ='Income Statement'!K41 -> 332.37 | ... L47: ='Income Statement'!M41 -> 368.24
B49: Sales Per share | C49: ='Income Statement'!D7/'Ratio Analysis'!C47 -> 934.06473 | D49: ='Income Statement'!E7/'Ratio Analysis'!D47 -> 1009.7686 | E49: ='Income Statement'!F7/'Ratio Analysis'!E47 -> 1045.7465 | F49: ='Income Statement'!G7/'Ratio Analysis'!F47 -> 845.15367 | G49: ='Income Statement'!H7/'Ratio Analysis'!G47 -> 752.32584 | H49: ='Income Statement'!I7/'Ratio Analysis'!H47 -> 838.53892 | I49: ='Income Statement'!J7/'Ratio Analysis'!I47 -> 1041.6613 | J49: ='Income Statement'!K7/'Ratio Analysis'!J47 -> 1305.8218 | ... L49: ='Income Statement'!M7/'Ratio Analysis'!L47 -> 911.31327 | N49: =AVERAGE(E49:L49) -> 966.87884 | O49: =MEDIAN(E49:L49) -> 952.89131
B50: Books per share | C50: =SUM('Balance Sheet'!D8:D9)/'Ratio Analysis'!C47 -> 201.09407 | D50: =SUM('Balance Sheet'!E8:E9)/'Ratio Analysis'!D47 -> 330.50916 | E50: =SUM('Balance Sheet'!F8:F9)/'Ratio Analysis'!E47 -> 208.4285 | F50: =SUM('Balance Sheet'!G8:G9)/'Ratio Analysis'!F47 -> 204.20372 | G50: =SUM('Balance Sheet'!H8:H9)/'Ratio Analysis'!G47 -> 166.39075 | H50: =SUM('Balance Sheet'!I8:I9)/'Ratio Analysis'!H47 -> 134.19231 | I50: =SUM('Balance Sheet'!J8:J9)/'Ratio Analysis'!I47 -> 136.45798 | J50: =SUM('Balance Sheet'!K8:K9)/'Ratio Analysis'!J47 -> 255.49237 | ... L50: =SUM('Balance Sheet'!M8:M9)/'Ratio Analysis'!L47 -> 304.33413 | N50: =AVERAGE(E50:L50) -> 215.62463 | O50: =MEDIAN(E50:L50) -> 206.31611
B51: Earning Per Share | C51: ='Income Statement'!D38/'Ratio Analysis'!C47 -> 21.000797 | D51: ='Income Statement'!E38/'Ratio Analysis'!D47 -> 23.596786 | E51: ='Income Statement'!F38/'Ratio Analysis'!E47 -> -100.21023 | F51: ='Income Statement'!G38/'Ratio Analysis'!F47 -> -35.530042 | G51: ='Income Statement'!H38/'Ratio Analysis'!G47 -> -44.228413 | H51: ='Income Statement'!I38/'Ratio Analysis'!H47 -> -33.832325 | I51: ='Income Statement'!J38/'Ratio Analysis'!I47 -> 8.0988468 | J51: ='Income Statement'!K38/'Ratio Analysis'!J47 -> 90.053254 | ... L51: ='Income Statement'!M38/'Ratio Analysis'!L47 -> 166.36161 | N51: =AVERAGE(E51:L51) -> 11.235116 | O51: =MEDIAN(E51:L51) -> -12.866739
B53: P/S Ratio | C53: =$C$45/C49 -> 0.35811223 | D53: =$C$45/D49 -> 0.33126402 | E53: =$C$45/E49 -> 0.31986718 | F53: =$C$45/F49 -> 0.39578601 | G53: =$C$45/G49 -> 0.44462117 | H53: =$C$45/H49 -> 0.39890814 | I53: =$C$45/I49 -> 0.32112165 | J53: =$C$45/J49 -> 0.25616052 | ... L53: =$C$45/L49 -> 0.3670527 | N53: =AVERAGE(E53:L53) -> 0.35498471 | O53: =MEDIAN(E53:L53) -> 0.3517065
B54: P/B Ratio | C54: =$C$45/C50 -> 1.6634006 | D54: =$C$45/D50 -> 1.0120748 | E54: =$C$45/E50 -> 1.6048669 | F54: =$C$45/F50 -> 1.63807 | G54: =$C$45/G50 -> 2.0103281 | H54: =$C$45/H50 -> 2.4926913 | I54: =$C$45/I50 -> 2.451304 | J54: =$C$45/J50 -> 1.3092367 | ... L54: =$C$45/L50 -> 1.0991209 | N54: =AVERAGE(E54:L54) -> 1.7082311 | O54: =MEDIAN(E54:L54) -> 1.6214685
B55: P/E Ratio | C55: =$C$45/C51 -> 15.927967 | D55: =$C$45/D51 -> 14.175659 | E55: =$C$45/E51 -> -3.3379825 | F55: =$C$45/F51 -> -9.4145681 | G55: =$C$45/G51 -> -7.5630116 | H55: =$C$45/H51 -> -9.8869943 | I55: =$C$45/I51 -> 41.302176 | J55: =$C$45/J51 -> 3.7144688 | ... L55: =$C$45/L51 -> 2.0106802 | N55: =AVERAGE(E55:L55) -> 3.1706067 | O55: =MEDIAN(E55:L55) -> -0.66365116

Sheet Forecasting
B2: ="Forecasting "&'Data Sheet'!B1 -> Forecasting TATA MOTORS PASSENGER VEHICLES LTD
B4: Year Weight | C4: Year | D4: Sales | E4: Sales Growth | G4: Year Weight | H4: Year | I4: EBIT | J4: EBIT Growth | L4: Year Weight | M4: Year | N4: PAT | O4: PAT Growth
B5: 1 | C5: {=TRANSPOSE('Cash Flow Statement'!D3:M3)} -> 42825 | D5: {=TRANSPOSE('Income Statement'!D7:M7)} -> 269692.51 | G5: 1 | H5: {=TRANSPOSE('Income Statement'!D4:M4)} -> 42825 | I5: {=TRANSPOSE('Income Statement'!D27:M27)} -> 13552.8 | L5: 1 | M5: {=TRANSPOSE('Income Statement'!D4:M4)} -> 42825 | N5: {=TRANSPOSE('Income Statement'!D38:M38)} -> 6063.56
B6: =B5+1 -> 2 | C6: 43190 | D6: 291550.48 | E6: =D6/D5-1 -> 0.081047746 | G6: =G5+1 -> 2 | H6: 43190 | I6: 15836.82 | J6: =I6/I5-1 -> 0.16852754 | L6: =L5+1 -> 2 | M6: 43190 | N6: 6813.1 | O6: =N6/N5-1 -> 0.12361385
B7: =B6+1 -> 3 | C7: 43555 | D7: 301938.4 | E7: =D7/D6-1 -> 0.035629919 | G7: =G6+1 -> 3 | H7: 43555 | I7: -25612.55 | J7: =I7/I6-1 -> -2.6172786 | L7: =L6+1 -> 3 | M7: 43555 | N7: -28933.7 | O7: =N7/N6-1 -> -5.2467746
B8: =B7+1 -> 4 | C8: 43921 | D8: 261067.97 | E8: =D8/D7-1 -> -0.13536016 | G8: =G7+1 -> 4 | H8: 43921 | I8: -3336.65 | J8: =I8/I7-1 -> -0.86972597 | L8: =L7+1 -> 4 | M8: 43921 | N8: -10975.23 | O8: =N8/N7-1 -> -0.62067658
B9: =B8+1 -> 5 | C9: 44286 | D9: 249794.75 | E9: =D9/D8-1 -> -0.043181168 | G9: =G8+1 -> 5 | H9: 44286 | I9: -4046.13 | J9: =I9/I8-1 -> 0.21263243 | L9: =L8+1 -> 5 | M9: 44286 | N9: -14685.16 | O9: =N9/N8-1 -> 0.33802754
B10: =B9+1 -> 6 | C10: 44651 | D10: 278453.62 | E10: =D10/D9-1 -> 0.11472967 | G10: =G9+1 -> 6 | H10: 44651 | I10: 2308.45 | J10: =I10/I9-1 -> -1.5705328 | L10: =L9+1 -> 6 | M10: 44651 | N10: -11234.7 | O10: =N10/N9-1 -> -0.23496237
B11: =B10+1 -> 7 | C11: 45016 | D11: 345966.97 | E11: =D11/D10-1 -> 0.24245815 | G11: =G10+1 -> 7 | H11: 45016 | I11: 13619.41 | J11: =I11/I10-1 -> 4.8998072 | L11: =L10+1 -> 7 | M11: 45016 | N11: 2689.87 | O11: =N11/N10-1 -> -1.2394252
B12: =B11+1 -> 8 | C12: 45382 | D12: 434016 | E12: =D12/D11-1 -> 0.25450126 | G12: =G11+1 -> 8 | H12: 45382 | I12: 33501 | J12: =I12/I11-1 -> 1.4597982 | L12: =L11+1 -> 8 | M12: 45382 | N12: 29931 | O12: =N12/N11-1 -> 10.127304
B13: =B12+1 -> 9 | C13: 45747 | D13: 366094 | E13: =D13/D12-1 -> -0.15649653 | G13: =G12+1 -> 9 | H13: 45747 | I13: 27380 | J13: =I13/I12-1 -> -0.18271096 | L13: =L12+1 -> 9 | M13: 45747 | N13: 14419 | O13: =N13/N12-1 -> -0.51825866
B14: =B13+1 -> 10 | C14: 46112 | D14: 335582 | E14: =D14/D13-1 -> -0.083344715 | G14: =G13+1 -> 10 | H14: 46112 | I14: 63842 | J14: =I14/I13-1 -> 1.331702 | L14: =L13+1 -> 10 | M14: 46112 | N14: 61261 | O14: =N14/N13-1 -> 3.2486303
